Workbook

Sheet 项目预算表-项目决算表
A1: 财务预算表 | K1: 财务决算表
A2: *会议名称 | B2: 鱼鹰号+活动名称 | F2: *项目所属部门 | G2: 厦门智海王潮会议展览有限公司 | K2: *公司人员参与执行人数：正式员工 个；试用期员工 个；实习生 个；其他人员 个；共计 个；
A3: *日程安排 | B3: 年/月/日 | F3: *会议 人数 | G3: 人数 | K3: *合同情况说明：
F4: *会议负责人 | G4: 会议负责人
F5: *会议报账人 | G5: 会议报账人
A6: 项目摘要 | C6: 预计收入 | G6: 预计成本 | K6: 实际收入 | O6: 实际成本 | S6: 备注
A7: 板块 | B7: 摘要 | C7: 预计单价 | D7: 预计数量 | E7: 预计次数 | F7: 预计收入单项小计 | G7: 预计单价 | H7: 预计数量 | I7: 预计次数 | J7: 预计成本单项小计 | K7: 实际单价 | L7: 实际数量 | M7: 实际次数 | N7: 实际收入单项小计 | O7: 实际单价 | P7: 实际数量 | Q7: 实际次数 | R7: 实际成本单项小计
C8: 0 | D8: 1 | E8: 1 | F8: =C8*D8*E8 -> 0 | G8: 0 | H8: 1 | I8: 1 | J8: =G8*H8*I8 -> 0
C9: 0 | D9: 1 | E9: 1 | F9: =C9*D9*E9 -> 0 | G9: 0 | H9: 1 | I9: 1 | J9: =G9*H9*I9 -> 0
C10: 0 | D10: 1 | E10: 1 | F10: =C10*D10*E10 -> 0 | G10: 0 | H10: 1 | I10: 1 | J10: =G10*H10*I10 -> 0
C11: 0 | D11: 1 | E11: 1 | F11: =C11*D11*E11 -> 0 | G11: 0 | H11: 1 | I11: 1 | J11: =G11*H11*I11 -> 0
C12: 0 | D12: 1 | E12: 1 | F12: =C12*D12*E12 -> 0 | G12: 0 | H12: 1 | I12: 1 | J12: =G12*H12*I12 -> 0
C13: 0 | D13: 1 | E13: 1 | F13: =C13*D13*E13 -> 0 | G13: 0 | H13: 1 | I13: 1 | J13: =G13*H13*I13 -> 0
C14: 0 | D14: 1 | E14: 1 | F14: =C14*D14*E14 -> 0 | G14: 0 | H14: 1 | I14: 1 | J14: =G14*H14*I14 -> 0
C15: 0 | D15: 1 | E15: 1 | F15: =C15*D15*E15 -> 0 | G15: 0 | H15: 1 | I15: 1 | J15: =G15*H15*I15 -> 0
C16: 0 | D16: 1 | E16: 1 | F16: =C16*D16*E16 -> 0 | G16: 0 | H16: 1 | I16: 1 | J16: =G16*H16*I16 -> 0
C17: 0 | D17: 1 | E17: 1 | F17: =C17*D17*E17 -> 0 | G17: 0 | H17: 1 | I17: 1 | J17: =G17*H17*I17 -> 0
C18: 0 | D18: 1 | E18: 1 | F18: =C18*D18*E18 -> 0 | G18: 0 | H18: 1 | I18: 1 | J18: =G18*H18*I18 -> 0
C19: 0 | D19: 1 | E19: 1 | F19: =C19*D19*E19 -> 0 | G19: 0 | H19: 1 | I19: 1 | J19: =G19*H19*I19 -> 0
... C54: 0 | D54: 1 | E54: 1 | F54: =C54*D54*E54 -> 0 | G54: 0 | H54: 1 | I54: 1 | J54: =G54*H54*I54 -> 0
A55: 平面延展设计 | B55: 主视觉设计、延展画面输出 | C55: 0 | D55: 1 | E55: 1 | F55: =C55*D55*E55 -> 0 | G55: 0 | H55: 1 | I55: 1 | J55: =G55*H55*I55 -> 0
A56: 酒店部分 | B56: 茶歇费用 | C56: 0 | D56: 1 | E56: 1 | F56: =C56*D56*E56 -> 0 | G56: 0 | H56: 1 | I56: 1 | J56: =G56*H56*I56 -> 0
B57: 会场租赁费 | C57: 0 | D57: 1 | E57: 1 | F57: =C57*D57*E57 -> 0 | G57: 0 | H57: 1 | I57: 1 | J57: =G57*H57*I57 -> 0
B58: 酒店住宿费 | C58: 0 | D58: 1 | E58: 1 | F58: =C58*D58*E58 -> 0 | G58: 0 | H58: 1 | I58: 1 | J58: =G58*H58*I58 -> 0
B59: 酒店餐饮费 | C59: 0 | D59: 1 | E59: 1 | F59: =C59*D59*E59 -> 0 | G59: 0 | H59: 1 | I59: 1 | J59: =G59*H59*I59 -> 0
A60: 大交通 | B60: 机票费用 | C60: 0 | D60: 1 | E60: 1 | F60: =C60*D60*E60 -> 0 | G60: 0 | H60: 1 | I60: 1 | J60: =G60*H60*I60 -> 0
B61: 动车费用 | C61: 0 | D61: 1 | E61: 1 | F61: =C61*D61*E61 -> 0 | G61: 0 | H61: 1 | I61: 1 | J61: =G61*H61*I61 -> 0
A62: 代付服务费用5% | B62: =SUM(F57:F61) -> 0 | C62: =B62 -> 0 | D62: 1 | E62: 1 | F62: =C62*D62*E62 -> 0
B63: 小计（不含代付服务费&代付费用） | F63: =SUM(F8:F62) -> 0 | N63: =SUM(N20:N20) -> 0 | R63: =SUM(R20:R20) -> 0
B64: 小计 | F64: =SUM(F8:F62) -> 0 | J64: =SUM(J19:J54)+K8 -> 0 | N64: =SUM(N21:N21) -> 0 | R64: =SUM(R21:R21) -> 0
A65: 操作 费用 模版 | B65: 餐饮费 | G65: 70 | H65: 1 | I65: 1 | J65: =G65*H65*I65 -> 70
B66: 交通费 | G66: 1000 | H66: 1 | I66: 1 | J66: =G66*H66*I66 -> 1000
B67: 招待费 | J67: =G67*H67*I67 -> 0
B68: 其他操作费 | J68: =G68*H68*I68 -> 0
B69: 物料费 | G69: 0 | H69: 1 | I69: 1 | J69: =G69*H69*I69 -> 0
B70: 小费 | J70: =G70*H70*I70 -> 0
B71: 住宿费 | G71: 300 | H71: 1 | I71: 1 | J71: =G71*H71*I71 -> 300
B72: 车辆补助 | J72: =G72*H72*I72 -> 0
B73: 人员补助 | G73: 120 | H73: 1 | I73: 1 | J73: =G73*H73*I73 -> 120 | S73: 实习生1位
B74: 部门补贴 | J74: =G74*H74*I74 -> 0
...

Sheet 预算-用款申请表  
B1: 预算用款申请表
A2: 会议名称 | B2: 鱼鹰号+活动名称
A3: 供应商 使用时间 | B3: 申请付款内容 | C3: 金额 | D3: 付款方式 点击选择 | E3: 付款时间 | F3: 供应商名称 | G3: 备注 | H3: 经办人
A4: 46257 | B4: 项目成本-设计费用 | C4: 0 | D4: 待转帐 | E4: 46257 | H4: 李蒙
A5: 46257 | B5: 项目成本-酒店代付 | C5: 0 | D5: 待转帐 | E5: 46257
A6: 46257 | B6: 项目成本-搭建 | C6: 0 | D6: 待转帐 | E6: 46257 | H6: 李蒙
A7: 46257 | B7: 项目成本-摄影摄像 | C7: 0 | D7: 待转帐 | E7: 46257 | H7: 李蒙
A8: 46257 | B8: 项目成本-大交通（票务） | C8: ='项目预算表-项目决算表'!G66 -> 1000 | D8: 待转帐 | E8: 46257 | H8: 李蒙
A9: 46257 | B9: 项目成本-会务执行 | C9: 0 | D9: 待转帐 | E9: 46257 | H9: 李蒙
A10: 46257 | B10: 项目成本-物料制作 | C10: ='项目预算表-项目决算表'!J69 -> 0 | D10: 现金 | E10: 46257 | H10: 李蒙
A11: 46257 | B11: 操作费用-餐饮费 | C11: ='项目预算表-项目决算表'!J65 -> 70 | D11: 现金 | E11: 46257 | H11: 李蒙
A12: 46257 | B12: 操作费用-交通费 | C12: 0 | D12: 现金 | E12: 46257
A13: 46257 | B13: 操作费用-物料费 | C13: ='项目预算表-项目决算表'!J69 -> 0 | D13: 现金 | E13: 46257 | H13: 李蒙
A14: 46257 | B14: 操作费用-住宿费 | C14: ='项目预算表-项目决算表'!J69 -> 0 | D14: 现金 | E14: 46257 | H14: 李蒙
A15: 46257 | B15: 项目成本-人补 | C15: ='项目预算表-项目决算表'!J73 -> 120 | D15: 待转帐 | E15: 46257 | H15: 李蒙
A16: 46257 | B16: 项目成本-税金 | C16: {='项目预算表-项目决算表'!F84:F85} -> 0 | D16: 待转帐 | E16: 46257 | H16: 李蒙
B17: 如果“行”不够使用请从此“行”往上插入行，插入的行即可含有此板块的公式；如有疑问可咨询财务部；打印时可删除此行； | C17: 0
B18: 小计 | C18: =SUM(C4:C16) -> 1190
B19: 已转帐 | C19: =SUMIF($D$4:$D$13,B19,$C$4:$C$13) -> 0
B20: 待转帐 | C20: =SUMIF($D$4:$D$16,B20,$C$4:$C$16) -> 1120
B21: 刷卡 | C21: =SUMIF($D$4:$D$13,B21,$C$4:$C$13) -> 0
B22: 现金 | C22: =SUMIF($D$4:$D$16,B22,$C$4:$C$16) -> 70
B23: 总计 | C23: =SUM(C19:C22) -> 1190 | D23: 金额和《项目预算表》预计成本金额一致
B24: 审核人： | D24: 制表人：

Sheet 填写首页
A1: 团队结算表格
A2: 财务主表
A3: 表格使用基本要求 | B3: 可自行添加“行”或删除“行”，但“列”框架不变；
A4: 表格打印须知 | B4: 在不改变“列”宽的前提下，可直接打印；
A5: 活动准备阶段-主表1 | B5: 《项目预算表》 | C5: 点击进入填写
A6: 活动准备阶段-主表2 | B6: 《用款申请表》 | C6: 点击进入填写
A7: 活动报账阶段-主表1 | B7: 《项目收支明细表》 | C7: 点击进入填写
A8: 活动报账阶段-主表2 | B8: 《项目结算表》 | C8: 点击进入填写
A9: 活动报账阶段-主表3 | B9: 《项目清算表》 | C9: 点击进入填写
A10: 财务附表
A11: 活动报账阶段-附表 | B11: 《协作人奖金表》 | C11: 点击进入填写
A12: 活动报账阶段-附表 | B12: 《人员补助表》 | C12: 点击进入填写
A13: 活动报账阶段-附表 | B13: 《车辆补贴表》 | C13: 点击进入填写
A14: 活动报账阶段-附表（针对旅行社活动） | B14: 《旅游团队名单表》 | C14: 点击进入填写

Sheet 人员补助表
A1: 会议人员补助明细表
A2: 鱼鹰号+会议名称
A3: 姓名 | B3: 级别 | C3: 部门 | D3: 活动日期 | E3: 工作时间 | F3: 人力成本 （元/天） | G3: 人员补贴 （元/天） | H3: 部门补贴 （元/天） | I3: 天数 | J3: 小计 | M3: 工作内容
J4: 人员补贴 | K4: 部门补贴 | L4: 人力成本
A5: 李蒙 | B5: 项目专员 | C5: 厦门项目二部 | D5: 年/月/日 | E5: 年/月/日 | G5: 120 | I5: 1 | J5: =SUM(G5*I5) -> 120
A6: 合计 | G6: =SUM(G5:G5) -> 120 | J6: =SUM(J5:J5) -> 120 | K6: =SUM(K5:K5) -> 0 | L6: =SUM(L5:L5) -> 0
A8: 制表人：王锦燦 | D8: 制表日期：2026年8月14日 | I8: 领导审核：
A10: 人力成本及补贴标准
A11: 级别 | D11: 人力成本 | E11: 人员补贴
A12: 实习生/试用期人员 | D12: 120 | E12: 70
A13: 项目专员/项目主任 | D13: 240 | E13: 120
A14: 执行副经理 | D14: 360 | E14: 120
A15: 执行经理/项目副经理 | D15: 460 | E15: 120
A16: 项目经理 | D16: 600 | E16: 120
A17: 助理高级经理 | D17: 600 | E17: 0
A18: 高级项目经理级以上 | D18: 800 | E18: 0

Sheet 结算-项目收支明细表
A1: 项目操作收支明细表
D2: 操作费用 | E2: 交通费 | J2: √
D3: 项目成本 | E3: 餐饮费
E4: 住宿费
C5: 项目借款 | D5: 备用金 | E5: 物料费
C6: 签单/酒店 | D6: 签单/酒店 | E6: 小费
E7: 人员补助
E8: 车辆补助
E9: 部门费用
E10: 其他操作费
E11: 项目成本
A12: 会议名称 | C12: 鱼鹰号+活动名称
A13: 现金收入
A14: 序号 | B14: 时间 | C14: 类型 点击选择 | D14: 明细 点击选择 | E14: 摘 要 | F14: 单价 | G14: 数量 | H14: 次数 | I14: 金 额 | J14: 发票 点击选择 | K14: 备 注 | L14: 经手人
B17: 如果“行”不够使用请从此“行”往上插入行，插入的行即可含有此板块的公式；如有疑问可咨询财务部；打印时可删除此行；
B18: 小 计 | I18: =SUM(I15:I17) -> 0
A19: 现金支出
A20: 序号 | B20: 时间 | C20: 类型 点击选择 | D20: 明细 点击选择 | E20: 摘 要 | F20: 单价 | G20: 数量 | H20: 次数 | I20: 金 额 | J20: 发票 点击选择 | K20: 备 注 | L20: 经手人
A63: 43
A64: 44
A65: 45
B67: 如果“行”不够使用请从此“行”往上插入行，插入的行即可含有此板块的公式；如有疑问可咨询财务部；打印时可删除此行；
B68: 小 计 | I68: =SUM(I21:I66) -> 0
D69: 小计
A70: 刷卡支出
A71: 1 | I71: =F71*G71*H71 -> 0
A72: 2 | I72: =F72*G72*H72 -> 0
B73: 如果“行”不够使用请从此“行”往上插入行，插入的行即可含有此板块的公式；如有疑问可咨询财务部；打印时可删除此行；
B74: 小 计 | I74: =SUM(I71:I73) -> 0
A75: 已转帐款项
B78: 如果“行”不够使用请从此“行”往上插入行，插入的行即可含有此板块的公式；如有疑问可咨询财务部；打印时可删除此行；
B79: 小计 | I79: =SUM(I76:I77) -> 0
A80: 未付款款项
B86: 如果“行”不够使用请从此“行”往上插入行，插入的行即可含有此板块的公式；如有疑问可咨询财务部；打印时可删除此行；
B87: 小计 | I87: =SUM(I81:I85) -> 0 | L87: 蒋巧俐
A88: 资金合计
B89: 现金 | I89: =I68 -> 0 | L89: 蒋巧俐
B90: 刷卡 | I90: =I74 -> 0 | L90: 蒋巧俐
B91: 已转帐 | I91: =I79 -> 0 | L91: 蒋巧俐
B92: 未付款 | I92: =I87 -> 0 | L92: 蒋巧俐
...

Sheet 项目清算表
C1: 请填写此颜色的相关内容，其他无需填写，可自动生成；按照单项毛利比率分摊操作费用支出、佣金、发票费用；
G2: 海南智海王潮会议展览有限公司
G3: 海南智海王潮会奖旅行社有限公司
G4: 海南智海王潮会奖旅行社有限公司三亚分公司
G5: 海口智海王潮文化传播有限公司
G6: 海南智海方舟公关顾问有限公司
G7: 海南智海方舟公关顾问有限公司三亚分公司
G8: 三亚智海王潮会议展览有限公司
G9: 北京智海王潮会议展览有限公司
G10: 海南智美飞扬广告传媒有限公司
G11: 三亚海勃互动商务服务有限公司
G12: 上海智海王潮会议展览有限公司
G13: 广州智海王潮会议展览有限公司
... G15: 无（不开发票）
A16: 项目结算清单
A17: 项目所属部门：厦门公司 | E17: 财务凭证号 | G17: 财务帐套编号 | I17: 营业报表编号
A18: 请勿修改表格格式，如有疑问咨询财务人员；*必填项；
A19: 项目信息 | C19: *项目名称 | H19: *开票金额（元） | I19: 11400
C20: *开始日期 | D20: 44973 | E20: *开票单位<点选> | F20: 厦门智海王潮会议展览有限公司 | H20: *结算金额（元） | I20: 11400
C21: *结束日期 | D21: 44981 | E21: *运作单位<点选> | F21: 厦门智海王潮会议展览有限公司 | H21: *多开发票（元） | I21: 0
C22: *会议天数 | D22: 9 | E22: *客户负责人 | F22: 戴娜茹 | H22: *预留收入（元） | I22: 0
C23: *会议人数 | D23: 500 | E23: *项目负责人 | F23: 戴娜茹 | H23: *截至报账未付款 | I23: 6636.62
C24: *报账日期 | D24: 44994 | E24: *项目报账人 | F24: 蒋巧俐 | H24: *截至报账未收款 | I24: 11400
A25: 项目名称 | B25: 名称 | D25: 收入 | E25: 成本 | F25: 原始毛利 | G25: 分摊成本 | H25: 分摊后毛利 | I25: 原始毛利率 | J25: 分摊后毛利率 | K25: 分摊后毛利指标
A26: 差旅板块01 | B26: 01 | C26: 会议住宿 | D26: 0 | E26: 0 | F26: =D26-E26 -> 0 | G26: =F26/($F$44-$F$39-$F$40-$F$41)*($E$39+$E$40+$E$41) -> 0 | H26: =D26-E26-G26 -> 0 | I26: =F26/D26 -> #DIV/0! | J26: =H26/D26 -> #DIV/0! | K26: =H26/$H$44 -> 0
B27: 02 | C27: 会议餐饮 | D27: 0 | E27: 0 | F27: =D27-E27 -> 0 | G27: =F27/($F$44-$F$39-$F$40-$F$41)*($E$39+$E$40+$E$41) -> 0 | H27: =D27-E27-G27 -> 0 | I27: =F27/D27 -> #DIV/0! | J27: =H27/D27 -> #DIV/0! | K27: =H27/$H$44 -> 0
B28: 03 | C28: 会议室租用 | D28: 0 | E28: 0 | F28: =D28-E28 -> 0 | G28: =F28/($F$44-$F$39-$F$40-$F$41)*($E$39+$E$40+$E$41) -> 0 | H28: =D28-E28-G28 -> 0 | I28: =F28/D28 -> #DIV/0! | J28: =H28/D28 -> #DIV/0! | K28: =H28/$H$44 -> 0
B29: 04 | C29: 会议接送车 | D29: 0 | E29: 0 | F29: =D29-E29 -> 0 | G29: =F29/($F$44-$F$39-$F$40-$F$41)*($E$39+$E$40+$E$41) -> 0 | H29: =D29-E29-G29 -> 0 | I29: =F29/D29 -> #DIV/0! | J29: =H29/D29 -> #DIV/0! | K29: =H29/$H$44 -> 0
B30: 05 | C30: 机票 | D30: 0 | E30: 0 | F30: =D30-E30 -> 0 | G30: =F30/($F$44-$F$39-$F$40-$F$41)*($E$39+$E$40+$E$41) -> 0 | H30: =D30-E30-G30 -> 0 | I30: =F30/D30 -> #DIV/0! | J30: =H30/D30 -> #DIV/0! | K30: =H30/$H$44 -> 0
B31: 06 | C31: 旅游 | D31: 0 | E31: 0 | F31: =D31-E31 -> 0 | G31: =F31/($F$44-$F$39-$F$40-$F$41)*($E$39+$E$40+$E$41) -> 0 | H31: =D31-E31-G31 -> 0 | I31: =F31/D31 -> #DIV/0! | J31: =H31/D31 -> #DIV/0! | K31: =H31/$H$44 -> 0
B32: 01 | C32: 摄影摄像 | D32: 0 | E32: 0 | F32: =D32-E32 -> 0 | G32: =F32/($F$44-$F$39-$F$40-$F$41)*($E$39+$E$40+$E$41) -> 0 | H32: =D32-E32-G32 -> 0 | I32: =F32/D32 -> #DIV/0! | J32: =H32/D32 -> #DIV/0! | K32: =H32/$H$44 -> 0
A33: 活动版块02 | B33: 02 | C33: 演艺演出 | D33: 0 | E33: 0 | F33: =D33-E33 -> 0 | G33: =F33/($F$44-$F$39-$F$40-$F$41)*($E$39+$E$40+$E$41) -> 0 | H33: =D33-E33-G33 -> 0 | I33: =F33/D33 -> #DIV/0! | J33: =H33/D33 -> #DIV/0! | K33: =H33/$H$44 -> 0
B34: 03 | C34: 广告板块 | D34: 0 | E34: 0 | F34: =D34-E34 -> 0 | G34: =F34/($F$44-$F$39-$F$40-$F$41)*($E$39+$E$40+$E$41) -> 0 | H34: =D34-E34-G34 -> 0 | I34: =F34/D34 -> #DIV/0! | J34: =H34/D34 -> #DIV/0! | K34: =H34/$H$44 -> 0
B35: 04 | C35: 搭建板块 | D35: 0 | E35: 0 | F35: =D35-E35 -> 0 | G35: =F35/($F$44-$F$39-$F$40-$F$41)*($E$39+$E$40+$E$41) -> 0 | H35: =D35-E35-G35 -> 0 | I35: =F35/D35 -> #DIV/0! | J35: =H35/D35 -> #DIV/0! | K35: =H35/$H$44 -> 0
B36: 05 | C36: A V板块 | D36: 0 | E36: 0 | F36: =D36-E36 -> 0 | G36: =F36/($F$44-$F$39-$F$40-$F$41)*($E$39+$E$40+$E$41) -> 0 | H36: =D36-E36-G36 -> 0 | I36: =F36/D36 -> #DIV/0! | J36: =H36/D36 -> #DIV/0! | K36: =H36/$H$44 -> 0
B37: 06 | C37: LED板块 | D37: 0 | E37: 0 | F37: =D37-E37 -> 0 | G37: =F37/($F$44-$F$39-$F$40-$F$41)*($E$39+$E$40+$E$41) -> 0 | H37: =D37-E37-G37 -> 0 | I37: =F37/D37 -> #DIV/0! | J37: =H37/D37 -> #DIV/0! | K37: =H37/$H$44 -> 0
A38: 其他杂项03 | B38: 01 | C38: 其他杂项 | D38: 11400 | E38: 0 | F38: =D38-E38 -> 11400 | G38: =F38/($F$44-$F$39-$F$40-$F$41)*($E$39+$E$40+$E$41) -> 8193.8234 | H38: =D38-E38-G38 -> 3206.1766 | I38: =F38/D38 -> 1 | J38: =H38/D38 -> 0.28124356 | K38: =H38/$H$44 -> 1.0398253
A39: 其他部分04 | B39: 01 | C39: 操作费用 | D39: 0 | E39: 7880 | F39: =D39-E39 -> -7880 | I39: =F39/D39 -> #DIV/0! | J39: =H39/D39 -> #DIV/0! | K39: =H39/$H$44 -> 0
B40: 02 | C40: 发票费用 | D40: 0 | E40: 0 | F40: =D40-E40 -> 0 | I40: =F40/D40 -> #DIV/0! | J40: =H40/D40 -> #DIV/0! | K40: =H40/$H$44 -> 0
B41: 03 | C41: 渠道费用 | D41: 0 | E41: 0 | F41: =D41-E41 -> 0 | I41: =F41/D41 -> #DIV/0! | J41: =H41/D41 -> #DIV/0! | K41: =H41/$H$44 -> 0
...
